Workbook

Sheet expl
A2: "+" GSV (CAB) | B2: Gross Sales Value | C2: = | D2: Price list w/o VAT * Qty | F2: price list w/o VAT | G2: = | H2: (Price list with VAT)/(100%+VAT)*100%
A3: "-" On invoice discount | B3: On | C3: = | D3: Discounts on the invoices
A4: "+" Invoiced Sales (CAF) | B4: Invoiced Sales | C4: = | D4: GSV - On * Qty
A5: "-" Off invoice discount | B5: Off | C5: = | D5: Retro bonuses (distributors)
A6: "-" Trade support | B6: Trade | C6: = | D6: Pharmacy chains
A8: "+" CANN (NSV) | B8: Net sales value | C8: = | D8: GSV - On - OFF - Trade
A9: NSP | B9: Net sales price | C9: = | D9: CANN/Qty
A11: "-" COGS | B11: Cost of goods sold | C11: = | D11: TP2+CD-IPU
A13: Managerial COGS | B13: TP2 + CD -IPU
A14: Operational COGS | B14: TP2 + CD
A16: TP2 | B16: SCP+PTC+IPU
A17: SCP | B17: Statistical cost price
A18: PTC | B18: Premier transport cost
A19: IPU | B19: Extra charge (2012 =38%)
A20: CD | B20: Custom Duties (2012 = 15,15%)
A22: "-" Logistics costs | B22: Log | C22: = | D22: costs of logistics department
A23: "+" CO | B23: Margin on Operations | C23: = | D23: CANN - COGS - Log
A25: "-" Marketing | B25: A&P | C25: = | D25: A&P costs
A26: "+" Net Product Contribution | C26: = | D26: CO - A&P
A28: "-" Sales Force | B28: SF | C28: = | D28: Sales force costs
A29: "+" Net Channel Contribution | C29: = | D29: CO - A&P - SF
A31: "-" Overheads | B31: OVHDS | C31: = | D31: OVHDs costs
A32: "+" Trading Operating Income | B32: ROP | C32: = | D32: CO - A&P - SF - OVHDs
A34: CO/CANN
A35: ROP/CANN

Sheet main
B1: Year | C1: 2023 | D1: 2023 | E1: 2023 | F1: 2023 | G1: 2023 | H1: 2023 | I1: 2023 | J1: 2023 | K1: 2023 | L1: 2023 | M1: 2023 | N1: 2023 | O1: 2024 | P1: 2024 | Q1: 2024 | R1: 2024 | S1: 2024 | T1: 2024 | U1: 2024 | V1: 2024 | W1: 2024 | X1: 2024 | Y1: 2024 | Z1: 2024 | AA1: 2025 | AB1: 2025 | AC1: 2025 | AD1: 2025 | AE1: 2025 | AF1: 2025 | AG1: 2025 | AH1: 2025 | AI1: 2025 | AJ1: 2025 | AK1: 2025 | AL1: 2025 | AM1: 2026 | AN1: 2026 | AO1: 2026 | AP1: 2026 | AQ1: 2026 | AR1: 2026 | AS1: 2026 | AT1: 2026 | AU1: 2026 | AV1: 2026 | AW1: 2026 | AX1: 2026
B2: Month | C2: 1 | D2: 2 | E2: 3 | F2: 4 | G2: 5 | H2: 6 | I2: 7 | J2: 8 | K2: 9 | L2: 10 | M2: 11 | N2: 12 | O2: 1 | P2: 2 | Q2: 3 | R2: 4 | S2: 5 | T2: 6 | U2: 7 | V2: 8 | W2: 9 | X2: 10 | Y2: 11 | Z2: 12 | AA2: 1 | AB2: 2 | AC2: 3 | AD2: 4 | AE2: 5 | AF2: 6 | AG2: 7 | AH2: 8 | AI2: 9 | AJ2: 10 | AK2: 11 | AL2: 12 | AM2: 1 | AN2: 2 | AO2: 3 | AP2: 4 | AQ2: 5 | AR2: 6 | AS2: 7 | AT2: 8 | AU2: 9 | AV2: 10 | AW2: 11 | AX2: 12
C3: Q1 | F3: Q2 | I3: Q3 | L3: Q4 | O3: Q1 | R3: Q2 | U3: Q3 | X3: Q4 | AA3: Q1 | AD3: Q2 | AG3: Q3 | AJ3: Q4 | AM3: Q1 | AP3: Q2 | AS3: Q3 | AV3: Q4
A4: Operational
B5: Количество новых скачиваний | U5: =U23 -> 39375 | V5: =V23 -> 39375 | W5: =W23 -> 39375 | X5: =X23 -> 51852.734 | Y5: =Y23 -> 58150.292 | Z5: =Z23 -> 60233.209 | AA5: =AA23 -> 60922.134 | AB5: =AB23 -> 84508.328 | ... AX5: =AX23 -> 101967.99
B6: Количество скачиваний итого | U6: =T6+U5 -> 39375 | V6: =U6+V5 -> 78750 | W6: =V6+W5 -> 118125 | X6: =W6+X5 -> 169977.73 | Y6: =X6+Y5 -> 228128.03 | Z6: =Y6+Z5 -> 288361.24 | AA6: =Z6+AA5 -> 349283.37 | AB6: =AA6+AB5 -> 433791.7 | ... AX6: =AW6+AX5 -> 5171700.3
B7: Прирост скачиваний
B8: Конверсия в платную подписку | U8: =U25 -> 0.01 | V8: =V25 -> 0.01 | W8: =W25 -> 0.01 | X8: =X25 -> 0.012 | Y8: =Y25 -> 0.012 | Z8: =Z25 -> 0.012 | AA8: =AA25 -> 0.014 | AB8: =AB25 -> 0.014 | ... AX8: =AX25 -> 0.024
B9: Новые подписки | C9: =C8*C5 -> 0 | D9: =D8*D5 -> 0 | E9: =E8*E5 -> 0 | F9: =F8*F5 -> 0 | G9: =G8*G5 -> 0 | H9: =H8*H5 -> 0 | I9: =I8*I5 -> 0 | J9: =J8*J5 -> 0 | ... AX9: =AX8*AX5 -> 2447.2318
B10: Подписчики итого | D10: =D9+C10 -> 0 | E10: =E9+D10 -> 0 | F10: =F9+E10 -> 0 | G10: =G9+F10 -> 0 | H10: =H9+G10 -> 0 | I10: =I9+H10 -> 0 | J10: =J9+I10 -> 0 | K10: =K9+J10 -> 0 | ... AX10: =AX9+AW10 -> 117332.4
B11: Campaign
B12: Campaign costs | U12: 5000 | V12: 5000 | W12: 5000 | X12: =W47 -> 2953.125 | Y12: =X47 -> 4666.7461 | Z12: =Y47 -> 5233.5263 | AA12: =Z47 -> 5420.9888 | AB12: =AA47 -> 6396.8241 | AC12: =AB47 -> 8873.3745 | AD12: =AC47 -> 9829.0134 | AE12: =AD47 -> 16025.068 | ... AX12: =AW47 -> 26930.066
B13: CPA | U13: =U12/U9 -> 12.698413 | V13: =V12/V9 -> 12.698413 | W13: =W12/W9 -> 12.698413 | X13: =X12/X9 -> 4.746013 | Y13: =Y12/Y9 -> 6.6877654 | Z13: =Z12/Z9 -> 7.2406434 | AA13: =AA12/AA9 -> 6.3558753 | AB13: =AB12/AB9 -> 5.4067571 | ... AX13: =AX12/AX9 -> 11.004297
B14: показы Impressions | U14: =U12/U15*1000 -> 6250000 | V14: =V12/V15*1000 -> 6250000 | W14: =W12/W15*1000 -> 6250000 | X14: =X12/X15*1000 -> 3691406.2 | Y14: =Y12/Y15*1000 -> 5833432.6 | Z14: =Z12/Z15*1000 -> 6541907.8 | AA14: =AA12/AA15*1000 -> 6776236 | AB14: =AB12/AB15*1000 -> 7996030.1 | ... AX14: =AX12/AX15*1000 -> 33662583
B15: стоимость показа CPM | U15: 0.8 | V15: 0.8 | W15: 0.8 | X15: 0.8 | Y15: 0.8 | Z15: 0.8 | AA15: 0.8 | AB15: 0.8 | AC15: 0.8 | AD15: 0.8 | AE15: 0.8 | AF15: 0.8 | AG15: 0.8 | AH15: 0.8 | AI15: 0.8 | AJ15: 0.8 | AK15: 0.8 | AL15: 0.8 | AM15: 0.8 | AN15: 0.8 | AO15: 0.8 | AP15: 0.8 | AQ15: 0.8 | AR15: 0.8 | AS15: 0.8 | AT15: 0.8 | AU15: 0.8 | AV15: 0.8 | AW15: 0.8 | AX15: 0.8
A16: 0.1029 | B16: CTR | U16: 0.021 | V16: 0.021 | W16: 0.021 | X16: 0.021 | Y16: 0.021 | Z16: 0.021 | AA16: 0.021 | AB16: 0.021 | AC16: 0.021 | AD16: 0.021 | AE16: 0.021 | AF16: 0.021 | AG16: 0.021 | AH16: 0.021 | AI16: 0.021 | AJ16: 0.021 | AK16: 0.021 | AL16: 0.021 | AM16: 0.021 | AN16: 0.021 | AO16: 0.021 | AP16: 0.021 | AQ16: 0.021 | AR16: 0.021 | AS16: 0.021 | AT16: 0.021 | AU16: 0.021 | AV16: 0.021 | AW16: 0.021 | AX16: 0.021
B17: Clicks | U17: =U14*U16 -> 131250 | V17: =V14*V16 -> 131250 | W17: =W14*W16 -> 131250 | X17: =X14*X16 -> 77519.531 | Y17: =Y14*Y16 -> 122502.09 | Z17: =Z14*Z16 -> 137380.06 | AA17: =AA14*AA16 -> 142300.96 | AB17: =AB14*AB16 -> 167916.63 | ... AX17: =AX14*AX16 -> 706914.23
A18: 1.39 | B18: CPC | U18: =U12/U17 -> 0.038095238 | V18: =V12/V17 -> 0.038095238 | W18: =W12/W17 -> 0.038095238 | X18: =X12/X17 -> 0.038095238 | Y18: =Y12/Y17 -> 0.038095238 | Z18: =Z12/Z17 -> 0.038095238 | AA18: =AA12/AA17 -> 0.038095238 | AB18: =AB12/AB17 -> 0.038095238 | ... AX18: =AX12/AX17 -> 0.038095238
B19: CR to download | U19: 0.14 | V19: 0.14 | W19: 0.14 | X19: 0.14 | Y19: 0.14 | Z19: 0.14 | AA19: 0.14 | AB19: 0.14 | AC19: 0.14 | AD19: 0.14 | AE19: 0.14 | AF19: 0.14 | AG19: 0.14 | AH19: 0.14 | AI19: 0.14 | AJ19: 0.14 | AK19: 0.14 | AL19: 0.14 | AM19: 0.14 | AN19: 0.14 | AO19: 0.14 | AP19: 0.14 | AQ19: 0.14 | AR19: 0.14 | AS19: 0.14 | AT19: 0.14 | AU19: 0.14 | AV19: 0.14 | AW19: 0.14 | AX19: 0.14
B20: paid downloads | U20: =U19*U17 -> 18375 | V20: =V19*V17 -> 18375 | W20: =W19*W17 -> 18375 | X20: =X19*X17 -> 10852.734 | Y20: =Y19*Y17 -> 17150.292 | Z20: =Z19*Z17 -> 19233.209 | AA20: =AA19*AA17 -> 19922.134 | AB20: =AB19*AB17 -> 23508.328 | ... AX20: =AX19*AX17 -> 98967.993
B21: organic downloads | U21: 20000 | V21: 20000 | W21: 20000 | X21: 40000 | Y21: 40000 | Z21: 40000 | AA21: 40000 | AB21: 60000 | AC21: 60000 | AD21: 60000 | AE21: 60000 | AF21: 60000 | AG21: 60000 | AH21: 60000 | AI21: 60000 | AJ21: 60000 | AK21: 60000 | AL21: 60000 | AM21: 60000 | AN21: 60000 | AO21: 60000 | AP21: 60000 | AQ21: 60000 | AR21: 60000 | AS21: 60000 | AT21: 2000 | AU21: 2000 | AV21: 2000 | AW21: 2000 | AX21: 2000
B22: referal downloads | U22: 1000 | V22: 1000 | W22: 1000 | X22: 1000 | Y22: 1000 | Z22: 1000 | AA22: 1000 | AB22: 1000 | AC22: 1000 | AD22: 1000 | AE22: 1000 | AF22: 1000 | AG22: 1000 | AH22: 1000 | AI22: 1000 | AJ22: 1000 | AK22: 1000 | AL22: 1000 | AM22: 1000 | AN22: 1000 | AO22: 1000 | AP22: 1000 | AQ22: 1000 | AR22: 1000 | AS22: 1000 | AT22: 1000 | AU22: 1000 | AV22: 1000 | AW22: 1000 | AX22: 1000
B23: total downloads | U23: =SUM(U20:U22) -> 39375 | V23: =SUM(V20:V22) -> 39375 | W23: =SUM(W20:W22) -> 39375 | X23: =SUM(X20:X22) -> 51852.734 | Y23: =SUM(Y20:Y22) -> 58150.292 | Z23: =SUM(Z20:Z22) -> 60233.209 | AA23: =SUM(AA20:AA22) -> 60922.134 | AB23: =SUM(AB20:AB22) -> 84508.328 | ... AX23: =SUM(AX20:AX22) -> 101967.99
A25: 4.86 | B25: CR to payemnt after trial | U25: 0.01 | V25: 0.01 | W25: 0.01 | X25: 0.012 | Y25: 0.012 | Z25: 0.012 | AA25: 0.014 | AB25: 0.014 | AC25: 0.014 | AD25: 0.022 | AE25: 0.022 | AF25: 0.022 | AG25: 0.024 | AH25: 0.024 | AI25: 0.024 | AJ25: 0.024 | AK25: 0.024 | AL25: 0.024 | AM25: 0.024 | AN25: 0.024 | AO25: 0.024 | AP25: 0.024 | AQ25: 0.024 | AR25: 0.024 | AS25: 0.024 | AT25: 0.024 | AU25: 0.024 | AV25: 0.024 | AW25: 0.024 | AX25: 0.024
B26: новые подписчики мес | U26: =U23*U25 -> 393.75 | V26: =V23*V25 -> 393.75 | W26: =W23*W25 -> 393.75 | X26: =X23*X25 -> 622.23281 | Y26: =Y23*Y25 -> 697.8035 | Z26: =Z23*Z25 -> 722.79851 | AA26: =AA23*AA25 -> 852.90987 | AB26: =AB23*AB25 -> 1183.1166 | ... AX26: =AX23*AX25 -> 2447.2318
B27: новые подписчики кампания ;мес( | U27: =U20*U25 -> 183.75 | V27: =V20*V25 -> 183.75 | W27: =W20*W25 -> 183.75 | X27: =X20*X25 -> 130.23281 | Y27: =Y20*Y25 -> 205.8035 | Z27: =Z20*Z25 -> 230.79851 | AA27: =AA20*AA25 -> 278.90987 | AB27: =AB20*AB25 -> 329.1166 | ... AX27: =AX20*AX25 -> 2375.2318
B28: итого подписчики | U28: =U26 -> 393.75 | V28: =U28+V26 -> 787.5 | W28: =V28+W26 -> 1181.25 | X28: =W28+X26 -> 1803.4828 | Y28: =X28+Y26 -> 2501.2863 | Z28: =Y28+Z26 -> 3224.0848 | AA28: =Z28+AA26 -> 4076.9947 | AB28: =AA28+AB26 -> 5260.1113 | AC28: =AB28+AC26 -> 6570.6464 | ... AX28: =AW28+AX26 -> 117332.4
B30: mrr | U30: =(U31/12)*U28 -> 820.3125 | V30: =(V31/12)*V28 -> 1640.625 | W30: =(W31/12)*W28 -> 2460.9375 | X30: =(X31/12)*X28 -> 3757.2559 | Y30: =(Y31/12)*Y28 -> 5211.0132 | Z30: =(Z31/12)*Z28 -> 6716.8434 | AA30: =(AA31/12)*AA28 -> 8493.739 | AB30: =(AB31/12)*AB28 -> 10958.565 | ... AX30: =(AX31/12)*AX28 -> 244442.49
B31: Годовая подписка | U31: 25 | V31: 25 | W31: 25 | X31: 25 | Y31: 25 | Z31: 25 | AA31: 25 | AB31: 25 | AC31: 25 | AD31: 25 | AE31: 25 | AF31: 25 | AG31: 25 | AH31: 25 | AI31: 25 | AJ31: 25 | AK31: 25 | AL31: 25 | AM31: 25 | AN31: 25 | AO31: 25 | AP31: 25 | AQ31: 25 | AR31: 25 | AS31: 25 | AT31: 25 | AU31: 25 | AV31: 25 | AW31: 25 | AX31: 25
B32: Процент возврата на подписку | AG32: 0.3 | AH32: 0.3 | AI32: 0.3 | AJ32: 0.3 | AK32: 0.3 | AL32: 0.3 | AM32: 0.25 | AN32: 0.25 | AO32: 0.25 | AP32: 0.2 | AQ32: 0.2 | AR32: 0.2 | AS32: 0.19 | AT32: 0.19 | AU32: 0.19 | AV32: 0.18 | AW32: 0.18 | AX32: 0.18
B33: Количество повторных подписчиков | AG33: =(AG32*AG9) -> 1022.919 | AH33: =(AH32*AH9) -> 1115.8609 | AI33: =(AI32*AI9) -> 1398.7846 | AJ33: =(AJ32*AJ9) -> 1642.0848 | AK33: =(AK32*AK9) -> 1851.3108 | AL33: =(AL32*AL9) -> 2031.2348 | AM33: =(AM32*AM9) -> 1821.6336 | AN33: =(AN32*AN9) -> 1872.2633 | ... AX33: =(AX32*AX9) -> 440.50173
B34: Выручка первичные оплаты | U34: =U9*U31 -> 9843.75 | V34: =V9*V31 -> 9843.75 | W34: =W9*W31 -> 9843.75 | X34: =X9*X31 -> 15555.82 | Y34: =Y9*Y31 -> 17445.088 | Z34: =Z9*Z31 -> 18069.963 | AA34: =AA9*AA31 -> 21322.747 | AB34: =AB9*AB31 -> 29577.915 | ... AX34: =AX9*AX31 -> 61180.796
B35: Выручка вторичные оплаты | AH35: =AH33*AH31 -> 27896.523 | AI35: =AI33*AI31 -> 34969.615 | AJ35: =AJ33*AJ31 -> 41052.121 | AK35: =AK33*AK31 -> 46282.771 | AL35: =AL33*AL31 -> 50780.869 | AM35: =AM33*AM31 -> 45540.84 | AN35: =AN33*AN31 -> 46806.582 | AO35: =AO33*AO31 -> 47853.193 | ... AX35: =AX33*AX31 -> 11012.543
B36: GSV total | U36: =SUM(U34:U35) -> 9843.75 | V36: =SUM(V34:V35) -> 9843.75 | W36: =SUM(W34:W35) -> 9843.75 | X36: =SUM(X34:X35) -> 15555.82 | Y36: =SUM(Y34:Y35) -> 17445.088 | Z36: =SUM(Z34:Z35) -> 18069.963 | AA36: =SUM(AA34:AA35) -> 21322.747 | AB36: =SUM(AB34:AB35) -> 29577.915 | ... AX36: =SUM(AX34:AX35) -> 72193.339
B37: динамика | V37: =(V36-U36)/U36 -> 0 | W37: =(W36-V36)/V36 -> 0 | X37: =(X36-W36)/W36 -> 0.58027381 | Y37: =(Y36-X36)/X36 -> 0.12145083 | Z37: =(Z36-Y36)/Y36 -> 0.035819548 | AA37: =(AA36-Z36)/Z36 -> 0.18001056 | AB37: =(AB36-AA36)/AA36 -> 0.38715313 | AC37: =(AC36-AB36)/AB36 -> 0.10769735 | ... AX37: =(AX36-AW36)/AW36 -> -0.19576871
A41: Marketing
B42: Количество лидов | C42: =C5 | D42: =D5 | E42: =E5 | F42: =F5 | G42: =G5 | H42: =H5 | I42: =I5 | J42: =J5 | ... AX42: =AX5 -> 101967.99
B43: Cost per lead (CPL) | U43: 0.1 | V43: 0.1 | W43: 0.1 | X43: 0.1 | Y43: 0.1 | Z43: 0.1 | AA43: 0.1 | AB43: 0.1 | AC43: 0.1 | AD43: 0.1 | AE43: 0.1 | AF43: 0.1 | AG43: 0.1 | AH43: 0.1 | AI43: 0.1 | AJ43: 0.1 | AK43: 0.1 | AL43: 0.1 | AM43: 0.1 | AN43: 0.1 | AO43: 0.1 | AP43: 0.1 | AQ43: 0.1 | AR43: 0.1 | AS43: 0.1 | AT43: 0.1 | AU43: 0.1 | AV43: 0.1 | AW43: 0.1 | AX43: 0.1
B44: CR% from lead to customer | U44: =U8 -> 0.01 | V44: =V8 -> 0.01 | W44: =W8 -> 0.01 | X44: =X8 -> 0.012 | Y44: =Y8 -> 0.012 | Z44: =Z8 -> 0.012 | AA44: =AA8 -> 0.014 | AB44: =AB8 -> 0.014 | ... AX44: =AX8 -> 0.024
B45: Cost per customer (CAC) | C45: 0 | D45: =IFERROR((D43*D42)/D9,0) -> 0 | E45: =IFERROR((E43*E42)/E9,0) -> 0 | F45: =IFERROR((F43*F42)/F9,0) -> 0 | G45: =IFERROR((G43*G42)/G9,0) -> 0 | H45: =IFERROR((H43*H42)/H9,0) -> 0 | I45: =IFERROR((I43*I42)/I9,0) -> 0 | J45: =IFERROR((J43*J42)/J9,0) -> 0 | K45: =IFERROR((K43*K42)/K9,0) -> 0 | ... AX45: =IFERROR((AX43*AX42)/AX9,0) -> 4.1666667
...

Sheet fin mod v.2
A1: * все суммы указаны в Евро | B1: Q1 | E1: Q2 | H1: Q3 | K1: Q4
B2: 2026 | C2: 2026 | D2: 2026 | E2: 2026 | F2: 2026 | G2: 2026 | H2: 2026 | I2: 2026 | J2: 2026 | K2: 2026 | L2: 2026 | M2: 2026
B3: jan | C3: feb | D3: mar | E3: apr | F3: may | G3: jun | H3: jul | I3: aug | J3: sep | K3: oct | L3: nov | M3: dec | O3: explanation
A4: Бюджет создание контента | G4: =G5*G6 -> 25000 | H4: =H5*H6 -> 29250 | I4: =I5*I6 -> 33800 | J4: =J5*J6 -> 38447.5 | K4: =K5*K6 -> 42841.5 | L4: =L5*L6 -> 46411.625 | M4: =M5*M6 -> 48268.09
A5: Единиц контента (ролики) | G5: 5000 | H5: =G5*1.3 -> 6500 | I5: =H5*1.3 -> 8450 | J5: =I5*1.3 -> 10985 | K5: =J5*1.3 -> 14280.5 | L5: =K5*1.3 -> 18564.65 | M5: =L5*1.3 -> 24134.045
A6: Стоимость ролика | G6: 5 | H6: =G6-0.5 -> 4.5 | I6: =H6-0.5 -> 4 | J6: =I6-0.5 -> 3.5 | K6: =J6-0.5 -> 3 | L6: =K6-0.5 -> 2.5 | M6: =L6-0.5 -> 2
A7: Количество аккаунтов | G7: =G5/50 -> 100 | H7: =H5/50 -> 130 | I7: =I5/50 -> 169 | J7: =J5/50 -> 219.7 | K7: =K5/50 -> 285.61 | L7: =L5/50 -> 371.293 | M7: =M5/50 -> 482.6809
A8: Охват ролика | G8: 3000 | H8: 3000 | I8: 3000 | J8: 3000 | K8: 3000 | L8: 3000 | M8: 3000
A9: Общий охват | G9: =G8*G5 -> 15000000 | H9: =H8*H5 -> 19500000 | I9: =I8*I5 -> 25350000 | J9: =J8*J5 -> 32955000 | K9: =K8*K5 -> 42841500 | L9: =L8*L5 -> 55693950 | M9: =M8*M5 -> 72402135
A10: CTR | G10: 0.0015 | H10: 0.0015 | I10: 0.0015 | J10: 0.0015 | K10: 0.0015 | L10: 0.0015 | M10: 0.0015
A11: Клики | G11: =G9*G10 -> 22500 | H11: =H9*H10 -> 29250 | I11: =I9*I10 -> 38025 | J11: =J9*J10 -> 49432.5 | K11: =K9*K10 -> 64262.25 | L11: =L9*L10 -> 83540.925 | M11: =M9*M10 -> 108603.2
A12: CR | G12: 0.02 | H12: 0.03 | I12: 0.03 | J12: 0.04 | K12: 0.04 | L12: 0.05 | M12: 0.05
A13: Заказы | G13: =G11*G12 -> 450 | H13: =H11*H12 -> 877.5 | I13: =I11*I12 -> 1140.75 | J13: =J11*J12 -> 1977.3 | K13: =K11*K12 -> 2570.49 | L13: =L11*L12 -> 4177.0463 | M13: =M11*M12 -> 5430.1601
A14: CPA EUR | G14: =G26/G13 -> 57.777778 | H14: =H26/H13 -> 34.814815 | I14: =I26/I13 -> 31.111111 | J14: =J26/J13 -> 20.555556 | K14: =K26/K13 -> 17.777778 | L14: =L26/L13 -> 12 | M14: =M26/M13 -> 9.7777778
A15: AOV | G15: =AVERAGE('Заводы + Юнит эк.'!AN4:AN8) -> 21.296 | H15: =G15*1.05 -> 22.3608 | I15: =H15*1.05 -> 23.47884 | J15: =I15*1.05 -> 24.652782 | K15: =J15*1.05 -> 25.885421 | L15: =K15*1.05 -> 27.179692 | M15: =L15*1.05 -> 28.538677
A16: заказы органика | H16: =G17*0.1 -> 45 | I16: =H17*0.1 -> 87.75 | J16: =I17*0.1 -> 114.075 | K16: =J17*0.1 -> 197.73 | L16: =K17*0.1 -> 257.049 | M16: =L17*0.1 -> 417.70463
A17: заказы контент завод | F17: =F13 | G17: =G13 -> 450 | H17: =H13 -> 877.5 | I17: =I13 -> 1140.75 | J17: =J13 -> 1977.3 | K17: =K13 -> 2570.49 | L17: =L13 -> 4177.0463 | M17: =M13 -> 5430.1601
A18: заказы повторные | G18: =F17*G21 -> 0 | H18: =G17*H21 -> 22.5 | I18: =H17*I21 -> 43.875 | J18: =I17*J21 -> 114.075 | K18: =J17*K21 -> 197.73 | L18: =K17*L21 -> 257.049 | M18: =L17*M21 -> 417.70463
A19: итого заказы | F19: =F17+F18 -> 0 | G19: =G17+G18+G16 -> 450 | H19: =H17+H18+H16 -> 945 | I19: =I17+I18+I16 -> 1272.375 | J19: =J17+J18+J16 -> 2205.45 | K19: =K17+K18+K16 -> 2965.95 | L19: =L17+L18+L16 -> 4691.1443 | M19: =M17+M18+M16 -> 6265.5694
A20: Retention
A21: процент повторных заказов | G21: 0.05 | H21: 0.05 | I21: 0.05 | J21: 0.1 | K21: 0.1 | L21: 0.1 | M21: 0.1
A22: средний чек в евро | G22: =G15 -> 21.296 | H22: =H15 -> 22.3608 | I22: =I15 -> 23.47884 | J22: =J15 -> 24.652782 | K22: =K15 -> 25.885421 | L22: =L15 -> 27.179692 | M22: =M15 -> 28.538677
A23: выручка в евро б/ндс | C23: =C19*C22 -> 0 | D23: =D19*D22 -> 0 | E23: =E19*E22 -> 0 | F23: =F22*F19 -> 0 | G23: =G22*G19 -> 9583.2 | H23: =H22*H19 -> 21130.956 | I23: =I22*I19 -> 29873.889 | J23: =J22*J19 -> 54370.478 | K23: =K22*K19 -> 76774.865 | L23: =L22*L19 -> 127503.86 | M23: =M22*M19 -> 178811.06
A24: ROAS | G24: =(G23/G26)*100% -> 0.36858462 | H24: =(H23/H26)*100% -> 0.69168432 | I24: =(I23/I26)*100% -> 0.84175512 | J24: =(J23/J26)*100% -> 1.3377081 | K24: =(K23/K26)*100% -> 1.6800634 | L24: =(L23/L26)*100% -> 2.5437404 | M24: =(M23/M26)*100% -> 3.3677634
A25: ДРР | G25: =G26/G23 -> 2.7130812 | H25: =H26/H23 -> 1.4457462 | I25: =I26/I23 -> 1.187994 | J25: =J26/J23 -> 0.74754723 | K25: =K26/K23 -> 0.59521564 | L25: =L26/L23 -> 0.39312187 | M25: =M26/M23 -> 0.29693297
A26: Расходы на маркетинг | D26: =D4 | F26: =F4 | G26: =G27+G28 -> 26000 | H26: =H27+H28 -> 30550 | I26: =I27+I28 -> 35490 | J26: =J27+J28 -> 40644.5 | K26: =K27+K28 -> 45697.6 | L26: =L27+L28 -> 50124.555 | M26: =M27+M28 -> 53094.899 | N26: =M26/M23 -> 0.29693297
A27: Создание контента | G27: =G4 -> 25000 | H27: =H4 -> 29250 | I27: =I4 -> 33800 | J27: =J4 -> 38447.5 | K27: =K4 -> 42841.5 | L27: =L4 -> 46411.625 | M27: =M4 -> 48268.09
A28: Технические расходы | G28: =G7*10 -> 1000 | H28: =H7*10 -> 1300 | I28: =I7*10 -> 1690 | J28: =J7*10 -> 2197 | K28: =K7*10 -> 2856.1 | L28: =L7*10 -> 3712.93 | M28: =M7*10 -> 4826.809
A31: ФОТ | B31: =payroll!B23 -> 0 | C31: =payroll!C23 -> 0 | D31: =payroll!D23 -> 0 | E31: =payroll!E23 -> 3961.1111 | F31: =payroll!F23 -> 5111.1111 | G31: =payroll!G23 -> 5111.1111 | H31: =payroll!H23 -> 5111.1111 | I31: =payroll!I23 -> 5111.1111 | ... M31: =payroll!M23 -> 5111.1111 | N31: =M31/M23 -> 0.028583865
A32: Коммерческие расходы | B32: =SUM(B34:B41)+B33 -> 0.2 | C32: =SUM(C34:C41)+C33 -> 0.2 | D32: =SUM(D34:D41)+D33 -> 0.2 | E32: =SUM(E34:E41)+E33 -> 51000.2 | F32: =SUM(F34:F41)+F33 -> 4000.2 | G32: =SUM(G34:G41)+G33 -> 2416.84 | H32: =SUM(H34:H41)+H33 -> 4726.3912 | I32: =SUM(I34:I41)+I33 -> 53474.978 | ... M32: =SUM(M34:M41)+M33 -> 36262.412
A33: Производство продукции | E33: 47000 | I33: 47000
A34: Регистрационные взносы | E34: 2000 | F34: 2000
A35: Консультанты | E35: 1000 | F35: 1000
A36: софт, подписки, опер расходы | E36: 1000 | F36: 1000 | G36: 500 | H36: 500 | I36: 500 | J36: 500 | K36: 500 | L36: 500 | M36: 500
A37: Комиссия Амазон | B37: 0.2 | C37: 0.2 | D37: 0.2 | E37: 0.2 | F37: 0.2 | G37: 0.2 | H37: 0.2 | I37: 0.2 | J37: 0.2 | K37: 0.2 | L37: 0.2 | M37: 0.2
A38: Комиссия Амазон евро | B38: =B23*B37 -> 0 | C38: =C23*C37 -> 0 | D38: =D23*D37 -> 0 | E38: =E23*E37 -> 0 | F38: =F23*F37 -> 0 | G38: =G23*G37 -> 1916.64 | H38: =H23*H37 -> 4226.1912 | I38: =I23*I37 -> 5974.7778 | ... M38: =M23*M37 -> 35762.212
A42: Logistics | B42: =B19*(B43+B44+B48+B49)+B47+B46 -> 0 | C42: =C19*(C43+C44+C48+C49)+C47+C46 -> 0 | D42: =D19*(D43+D44+D48+D49)+D47+D46 -> 0 | E42: =E19*(E43+E44+E48+E49)+E47+E46 -> 300 | F42: =F19*(F43+F44+F48+F49)+F47+F46 -> 300 | G42: =G19*(G43+G44+G48+G49)+G47+G46 -> 2257.5 | H42: =H19*(H43+H44+H48+H49)+H47+H46 -> 4399.275 | I42: =I19*(I43+I44+I48+I49)+I47+I46 -> 5798.955 | ... M42: =M19*(M43+M44+M48+M49)+M47+M46 -> 27544.496 | N42: =M42/M23 -> 0.15404247
A43: Доставка амазон-завод за ед | B43: 0.25 | C43: 0.25 | D43: 0.25 | E43: 0.25 | F43: 0.25 | G43: 0.25 | H43: 0.25 | I43: 0.25 | J43: 0.25 | K43: 0.25 | L43: 0.25 | M43: 0.25
A44: FBO Amazon за ед | B44: 4.13 | C44: 4.13 | D44: 4.13 | E44: 4.13 | F44: 4.13 | G44: 4.13 | H44: 4.13 | I44: 4.13 | J44: 4.13 | K44: 4.13 | L44: 4.13 | M44: 4.13
A45: Хранение Amazon за ед | B45: 0.03 | C45: 0.03 | D45: 0.03 | E45: 0.03 | F45: 0.03 | G45: 0.03 | H45: 0.03 | I45: 0.03 | J45: 0.03 | K45: 0.03 | L45: 0.03 | M45: 0.03
...

Sheet fin mod
A1: * все суммы указаны в Евро | B1: Q1 | E1: Q2 | H1: Q3 | K1: Q4
B2: 2026 | C2: 2026 | D2: 2026 | E2: 2026 | F2: 2026 | G2: 2026 | H2: 2026 | I2: 2026 | J2: 2026 | K2: 2026 | L2: 2026 | M2: 2026
B3: jan | C3: feb | D3: mar | E3: apr | F3: may | G3: jun | H3: jul | I3: aug | J3: sep | K3: oct | L3: nov | M3: dec | O3: explanation
A4: Бюджет маркетинг | G4: =G5*G6 -> 1500 | H4: =H5*H6 -> 1950 | I4: =I5*I6 -> 2535 | J4: =J5*J6 -> 3295.5 | K4: =K5*K6 -> 4284.15 | L4: =L5*L6 -> 5569.395 | M4: =M5*M6 -> 7240.2135
A5: Единиц контента (ролики) | G5: 5000 | H5: =G5*1.3 -> 6500 | I5: =H5*1.3 -> 8450 | J5: =I5*1.3 -> 10985 | K5: =J5*1.3 -> 14280.5 | L5: =K5*1.3 -> 18564.65 | M5: =L5*1.3 -> 24134.045
A6: Стоимость ролика | G6: 0.3 | H6: 0.3 | I6: 0.3 | J6: 0.3 | K6: 0.3 | L6: 0.3 | M6: 0.3
A7: Охват ролика | G7: 3000 | H7: 3000 | I7: 3000 | J7: 3000 | K7: 3000 | L7: 3000 | M7: 3000
A8: Общий охват | G8: =G7*G5 -> 15000000 | H8: =H7*H5 -> 19500000 | I8: =I7*I5 -> 25350000 | J8: =J7*J5 -> 32955000 | K8: =K7*K5 -> 42841500 | L8: =L7*L5 -> 55693950 | M8: =M7*M5 -> 72402135
A9: CTR | G9: 0.0015 | H9: 0.0015 | I9: 0.0015 | J9: 0.0015 | K9: 0.0015 | L9: 0.0015 | M9: 0.0015
A10: Клики | G10: =G8*G9 -> 22500 | H10: =H8*H9 -> 29250 | I10: =I8*I9 -> 38025 | J10: =J8*J9 -> 49432.5 | K10: =K8*K9 -> 64262.25 | L10: =L8*L9 -> 83540.925 | M10: =M8*M9 -> 108603.2
A11: CR | G11: 0.02 | H11: 0.03 | I11: 0.03 | J11: 0.04 | K11: 0.04 | L11: 0.05 | M11: 0.05
A12: Заказы | G12: =G10*G11 -> 450 | H12: =H10*H11 -> 877.5 | I12: =I10*I11 -> 1140.75 | J12: =J10*J11 -> 1977.3 | K12: =K10*K11 -> 2570.49 | L12: =L10*L11 -> 4177.0463 | M12: =M10*M11 -> 5430.1601
A13: AOV | G13: =AVERAGE('Заводы + Юнит эк.'!AN4:AN8) -> 21.296 | H13: =G13*1.05 -> 22.3608 | I13: =H13*1.05 -> 23.47884 | J13: =I13*1.05 -> 24.652782 | K13: =J13*1.05 -> 25.885421 | L13: =K13*1.05 -> 27.179692 | M13: =L13*1.05 -> 28.538677
A14: заказы органика | H14: =G15*0.1 -> 45 | I14: =H15*0.1 -> 87.75 | J14: =I15*0.1 -> 114.075 | K14: =J15*0.1 -> 197.73 | L14: =K15*0.1 -> 257.049 | M14: =L15*0.1 -> 417.70463
A15: заказы контент завод | F15: =F12 | G15: =G12 -> 450 | H15: =H12 -> 877.5 | I15: =I12 -> 1140.75 | J15: =J12 -> 1977.3 | K15: =K12 -> 2570.49 | L15: =L12 -> 4177.0463 | M15: =M12 -> 5430.1601
A16: заказы повторные | G16: =F15*G19 -> 0 | H16: =G15*H19 -> 22.5 | I16: =H15*I19 -> 43.875 | J16: =I15*J19 -> 114.075 | K16: =J15*K19 -> 197.73 | L16: =K15*L19 -> 257.049 | M16: =L15*M19 -> 417.70463
A17: итого заказы | F17: =F15+F16 -> 0 | G17: =G15+G16+G14 -> 450 | H17: =H15+H16+H14 -> 945 | I17: =I15+I16+I14 -> 1272.375 | J17: =J15+J16+J14 -> 2205.45 | K17: =K15+K16+K14 -> 2965.95 | L17: =L15+L16+L14 -> 4691.1443 | M17: =M15+M16+M14 -> 6265.5694
A18: Retention
A19: процент повторных заказов | G19: 0.05 | H19: 0.05 | I19: 0.05 | J19: 0.1 | K19: 0.1 | L19: 0.1 | M19: 0.1
A20: средний чек в евро | G20: =G13 -> 21.296 | H20: =H13 -> 22.3608 | I20: =I13 -> 23.47884 | J20: =J13 -> 24.652782 | K20: =K13 -> 25.885421 | L20: =L13 -> 27.179692 | M20: =M13 -> 28.538677
A21: выручка в евро б/ндс | C21: =C17*C20 -> 0 | D21: =D17*D20 -> 0 | E21: =E17*E20 -> 0 | F21: =F20*F17 -> 0 | G21: =G20*G17 -> 9583.2 | H21: =H20*H17 -> 21130.956 | I21: =I20*I17 -> 29873.889 | J21: =J20*J17 -> 54370.478 | K21: =K20*K17 -> 76774.865 | L21: =L20*L17 -> 127503.86 | M21: =M20*M17 -> 178811.06
A22: CPA | G22: =G4/G12 -> 3.3333333
A24: Расходы на маркетинг | D24: =D4 | F24: =F4 | G24: =G4 -> 1500 | H24: =H4 -> 1950 | I24: =I4 -> 2535 | J24: =J4 -> 3295.5 | K24: =K4 -> 4284.15 | L24: =L4 -> 5569.395 | M24: =M4 -> 7240.2135 | N24: =M24/M21 -> 0.04049086
A25: Costs
A26: Marketing cost rate
A27: Marketing costs EUR
A28: Costs of payment processing
A29: ФОТ | B29: =payroll!B23 -> 0 | C29: =payroll!C23 -> 0 | D29: =payroll!D23 -> 0 | E29: =payroll!E23 -> 3961.1111 | F29: =payroll!F23 -> 5111.1111 | G29: =payroll!G23 -> 5111.1111 | H29: =payroll!H23 -> 5111.1111 | I29: =payroll!I23 -> 5111.1111 | ... M29: =payroll!M23 -> 5111.1111 | N29: =M29/M21 -> 0.028583865
A30: Коммерческие расходы | B30: =SUM(B32:B39)+B31 -> 0.2 | C30: =SUM(C32:C39)+C31 -> 0.2 | D30: =SUM(D32:D39)+D31 -> 0.2 | E30: =SUM(E32:E39)+E31 -> 51000.2 | F30: =SUM(F32:F39)+F31 -> 4000.2 | G30: =SUM(G32:G39)+G31 -> 2416.84 | H30: =SUM(H32:H39)+H31 -> 4726.3912 | I30: =SUM(I32:I39)+I31 -> 53474.978 | ... M30: =SUM(M32:M39)+M31 -> 36262.412
A31: Производство продукции | E31: 47000 | I31: 47000
A32: Регистрационные взносы | E32: 2000 | F32: 2000
A33: Консультанты | E33: 1000 | F33: 1000
A34: софт, подписки, опер расходы | E34: 1000 | F34: 1000 | G34: 500 | H34: 500 | I34: 500 | J34: 500 | K34: 500 | L34: 500 | M34: 500
A35: Комиссия Амазон | B35: 0.2 | C35: 0.2 | D35: 0.2 | E35: 0.2 | F35: 0.2 | G35: 0.2 | H35: 0.2 | I35: 0.2 | J35: 0.2 | K35: 0.2 | L35: 0.2 | M35: 0.2
A36: Комиссия Амазон евро | B36: =B21*B35 -> 0 | C36: =C21*C35 -> 0 | D36: =D21*D35 -> 0 | E36: =E21*E35 -> 0 | F36: =F21*F35 -> 0 | G36: =G21*G35 -> 1916.64 | H36: =H21*H35 -> 4226.1912 | I36: =I21*I35 -> 5974.7778 | ... M36: =M21*M35 -> 35762.212
A40: Logistics | B40: =B17*(B41+B42+B46+B47)+B45+B44 -> 0 | C40: =C17*(C41+C42+C46+C47)+C45+C44 -> 0 | D40: =D17*(D41+D42+D46+D47)+D45+D44 -> 0 | E40: =E17*(E41+E42+E46+E47)+E45+E44 -> 300 | F40: =F17*(F41+F42+F46+F47)+F45+F44 -> 300 | G40: =G17*(G41+G42+G46+G47)+G45+G44 -> 2257.5 | H40: =H17*(H41+H42+H46+H47)+H45+H44 -> 4399.275 | I40: =I17*(I41+I42+I46+I47)+I45+I44 -> 5798.955 | ... M40: =M17*(M41+M42+M46+M47)+M45+M44 -> 27544.496 | N40: =M40/M21 -> 0.15404247
A41: Доставка амазон-завод за ед | B41: 0.25 | C41: 0.25 | D41: 0.25 | E41: 0.25 | F41: 0.25 | G41: 0.25 | H41: 0.25 | I41: 0.25 | J41: 0.25 | K41: 0.25 | L41: 0.25 | M41: 0.25
A42: FBO Amazon за ед | B42: 4.13 | C42: 4.13 | D42: 4.13 | E42: 4.13 | F42: 4.13 | G42: 4.13 | H42: 4.13 | I42: 4.13 | J42: 4.13 | K42: 4.13 | L42: 4.13 | M42: 4.13
A43: Хранение Amazon за ед | B43: 0.03 | C43: 0.03 | D43: 0.03 | E43: 0.03 | F43: 0.03 | G43: 0.03 | H43: 0.03 | I43: 0.03 | J43: 0.03 | K43: 0.03 | L43: 0.03 | M43: 0.03
A44: Хранение Amazon за тотал | B44: =B68*B43 -> 0 | C44: =C68*C43 -> 0 | D44: =D68*D43 -> 0 | E44: =E68*E43 -> 300 | F44: =F68*F43 -> 300 | G44: =G68*G43 -> 286.5 | H44: =H68*H43 -> 260.175 | I44: =I68*I43 -> 225.9525 | ... M44: =M68*M43 -> 101.30261
...

Sheet Заводы + Юнит эк.
A1: * All prices in EURO
J2: Merywood | Q2: MillMax | X2: ERA | AE2: Nutriliq | AO2: Scenario 2
A3: Brand | B3: SKU | C3: Substance | D3: Form | E3: Volume | F3: Pack | G3: Additional label | H3: Face label language | I3: additional languages | J3: MOQ | K3: price per SKU (w/o VAT) | L3: price per SKU | M3: VAT | N3: MOQ COST | O3: LT (weeks) | P3: Comment | Q3: MOQ | R3: price per SKU (w/o VAT) | S3: price per SKU | T3: VAT | U3: MOQ COST | V3: LT (weeks) | W3: Comment | X3: MOQ | Y3: price per SKU (w/o VAT) | Z3: price per SKU | AA3: VAT | AB3: MOQ COST | AC3: LT (weeks) | AD3: Comment | AE3: MOQ | AF3: price per SKU (w/o VAT) | AG3: price per SKU | AH3: VAT | AI3: MOQ COST | AJ3: LT (weeks) | AK3: Comment | AM3: Маржа: себес / РРЦ | AN3: AVG amazon price w/o VAT | AO3: COGS w/o VAT | AP3: OPEX | AQ3: OPEX+COGS | AS3: Gross profit EUR (до налогов) | AT3: Gross margin (до налогов) | AW3: Amazon comission | AX3: CPA | AY3: Logistics | AZ3: Payroll | BA3: Legal | BB3: Commercial others | BD3: CPA EUR | BF3: Payroll EUR | BG3: Amazon comission EUR | BH3: Logistics EUR | BI3: Legal EUR | BJ3: Commerical EUR | BL3: База для расчета налога EUR | BM3: Ставка налога в Болгарии Corporate tax | BN3: Налог к уплате EUR | BO3: Прибыль после уплаты налога | BP3: Маржинальность после уплаты налога
A4: QEEP | B4: Inositol | C4: 274 mg | D4: capsules | E4: 180 pc | F4: Bottle | G4: peel-off | H4: DE | I4: EN, FR, IT, ES | J4: 5000 | K4: 4.86 | L4: =K4*(1+M4) -> 4.86 | M4: 0 | N4: =J4*L4 -> 24300 | O4: 46240 | P4: Sticker registration service | Q4: 2000 | R4: 3.65 | S4: =R4*(1+T4) -> 3.65 | T4: 0 | U4: =S4*Q4 -> 7300 | V4: 46240 | X4: 1000 | Y4: 5.59 | Z4: =Y4*(1+AA4) -> 5.59 | AA4: 0 | AB4: =Z4*X4 -> 5590 | AC4: 46240 | AL4: MillMax | AM4: =1-(AO4/AN4) -> 0.85162602 | AN4: 24.6 | AO4: =R4 -> 3.65 | AP4: =BD4+BE4+BF4+BG4+BH4+BI4+BJ4 -> 11.75954 | AQ4: =AP4+AO4 -> 15.40954 | AS4: =AN4-AQ4 -> 9.19046 | AT4: =AS4/AN4 -> 0.37359593 | AW4: 0.2 | AX4: 0.035 | AY4: =BH4/AN4 -> 0.16788618 | AZ4: 0.0249 | BA4: 0.005 | BB4: 0.005 | BD4: =AX4*AN4 -> 0.861 | BF4: =AN4*AZ4 -> 0.61254 | BG4: =(AN4*AW4)+0.99 -> 5.91 | BH4: 4.13 | BI4: =AN4*BA4 -> 0.123 | BJ4: =AN4*BB4 -> 0.123 | BL4: =AN4-BG4-BH4-BI4-BJ4 -> 14.314 | BM4: 0.1 | BN4: =BL4*BM4 -> 1.4314 | BO4: =AS4-BN4 -> 7.75906 | BP4: =BO4/AN4 -> 0.31540894
A5: QEEP | B5: Magnesium B6 | C5: 635mg | D5: capsules | E5: 180 pc | F5: Bottle | G5: peel-off | H5: DE | I5: EN, FR, IT, ES | J5: 5000 | K5: 4.9 | L5: =K5*(1+M5) -> 4.9 | M5: 0 | N5: =J5*L5 -> 24500 | O5: 46177 | P5: Sticker registration service | Q5: 2000 | R5: 4.7 | S5: =R5*(1+T5) -> 4.7 | T5: 0 | U5: =S5*Q5 -> 9400 | V5: 46177 | X5: 1000 | Y5: 4.98 | Z5: =Y5*(1+AA5) -> 4.98 | AA5: 0 | AB5: =Z5*X5 -> 4980 | AC5: 46177 | AL5: MillMax | AM5: =1-(AO5/AN5) -> 0.74344978 | AN5: 18.32 | AO5: =R5 -> 4.7 | AP5: =BD5+BE5+BF5+BG5+BH5+BI5+BJ5 -> 10.064568 | AQ5: =AP5+AO5 -> 14.764568 | AS5: =AN5-AQ5 -> 3.555432 | AT5: =AS5/AN5 -> 0.1940738 | AW5: 0.2 | AX5: 0.035 | AY5: =BH5/AN5 -> 0.22543668 | AZ5: 0.0249 | BA5: 0.005 | BB5: 0.005 | BD5: =AX5*AN5 -> 0.6412 | BF5: =AN5*AZ5 -> 0.456168 | BG5: =(AN5*AW5)+0.99 -> 4.654 | BH5: 4.13 | BI5: =AN5*BA5 -> 0.0916 | BJ5: =AN5*BB5 -> 0.0916 | BL5: =AN5-BG5-BH5-BI5-BJ5 -> 9.3528 | BM5: 0.1 | BN5: =BL5*BM5 -> 0.93528 | BO5: =AS5-BN5 -> 2.620152 | BP5: =BO5/AN5 -> 0.1430214
A6: QEEP | B6: Probiotic Detox | D6: capsules | E6: 60 pc | F6: Bottle | G6: peel-off | H6: DE | I6: EN, FR, IT, ES | J6: 1000 | K6: 3.1 | L6: =K6*(1+M6) -> 3.1 | M6: 0 | N6: =J6*L6 -> 3100 | O6: 46177 | P6: Sticker registration service | S6: =R6*(1+T6) -> 0 | T6: 0 | U6: =S6*Q6 -> 0 | V6: 46177 | X6: 1000 | Y6: 4.07 | Z6: =Y6*(1+AA6) -> 4.07 | AA6: 0 | AB6: =Z6*X6 -> 4070 | AC6: 46177 | AL6: ERA | AM6: =1-(AO6/AN6) -> 0.86252772 | AN6: 22.55 | AO6: =K6 -> 3.1 | AP6: =BD6+BE6+BF6+BG6+BH6+BI6+BJ6 -> 11.206245 | AQ6: =AP6+AO6 -> 14.306245 | AS6: =AN6-AQ6 -> 8.243755 | AT6: =AS6/AN6 -> 0.36557672 | AW6: 0.2 | AX6: 0.035 | AY6: =BH6/AN6 -> 0.18314856 | AZ6: 0.0249 | BA6: 0.005 | BB6: 0.005 | BD6: =AX6*AN6 -> 0.78925 | BF6: =AN6*AZ6 -> 0.561495 | BG6: =(AN6*AW6)+0.99 -> 5.5 | BH6: 4.13 | BI6: =AN6*BA6 -> 0.11275 | BJ6: =AN6*BB6 -> 0.11275 | BL6: =AN6-BG6-BH6-BI6-BJ6 -> 12.6945 | BM6: 0.1 | BN6: =BL6*BM6 -> 1.26945 | BO6: =AS6-BN6 -> 6.974305 | BP6: =BO6/AN6 -> 0.30928182
A7: QEEP | B7: Retinol cream | C7: 0.005 | D7: cream | E7: 30 ml | F7: Airless spray bottle | G7: infolist | H7: DE | I7: EN, FR, IT, ES | J7: 5000 | K7: 3.5 | L7: =K7*(1+M7) -> 3.5 | M7: 0 | N7: =J7*L7 -> 17500 | O7: 46146 | P7: Sticker registration service | Q7: 5000 | R7: 3.15 | S7: =R7*(1+T7) -> 3.15 | T7: 0 | U7: =S7*Q7 -> 15750 | V7: 46146 | W7: Exclusive 6-12 months | X7: 1000 | Y7: 4.01 | Z7: =Y7*(1+AA7) -> 4.01 | AA7: 0 | AB7: =Z7*X7 -> 4010 | AC7: 46182 | AL7: Merywood | AM7: =1-(AO7/AN7) -> 0.82224479 | AN7: 19.69 | AO7: =K7 -> 3.5 | AP7: =BD7+BE7+BF7+BG7+BH7+BI7+BJ7 -> 10.434331 | AQ7: =AP7+AO7 -> 13.934331 | AS7: =AN7-AQ7 -> 5.755669 | AT7: =AS7/AN7 -> 0.29231432 | AW7: 0.2 | AX7: 0.035 | AY7: =BH7/AN7 -> 0.20975114 | AZ7: 0.0249 | BA7: 0.005 | BB7: 0.005 | BD7: =AX7*AN7 -> 0.68915 | BF7: =AN7*AZ7 -> 0.490281 | BG7: =(AN7*AW7)+0.99 -> 4.928 | BH7: 4.13 | BI7: =AN7*BA7 -> 0.09845 | BJ7: =AN7*BB7 -> 0.09845 | BL7: =AN7-BG7-BH7-BI7-BJ7 -> 10.4351 | BM7: 0.1 | BN7: =BL7*BM7 -> 1.04351 | BO7: =AS7-BN7 -> 4.712159 | BP7: =BO7/AN7 -> 0.23931737
A8: Harly | B8: Dog Probiotic | C8: 3g. chew | D8: soft chews | E8: 60 pc | F8: Bottle | G8: peel-off | H8: DE | I8: EN, FR, IT, ES | AE8: 890 | AF8: 5.19 | AG8: =AF8*(1+AH8) -> 5.19 | AH8: 0 | AI8: =AG8*AE8 -> 4619.1 | AJ8: 46240 | AL8: Nutriliq | AM8: =1-(AO8/AN8) -> 0.7565666 | AN8: 21.32 | AO8: =AF8 -> 5.19 | AP8: =BD8+BE8+BF8+BG8+BH8+BI8+BJ8 -> 10.874268 | AQ8: =AP8+AO8 -> 16.064268 | AS8: =AN8-AQ8 -> 5.255732 | AT8: =AS8/AN8 -> 0.24651651 | AW8: 0.2 | AX8: 0.035 | AY8: =BH8/AN8 -> 0.19371482 | AZ8: 0.0249 | BA8: 0.005 | BB8: 0.005 | BD8: =AX8*AN8 -> 0.7462 | BF8: =AN8*AZ8 -> 0.530868 | BG8: =(AN8*AW8)+0.99 -> 5.254 | BH8: 4.13 | BI8: =AN8*BA8 -> 0.1066 | BJ8: =AN8*BB8 -> 0.1066 | BL8: =AN8-BG8-BH8-BI8-BJ8 -> 11.7228 | BM8: 0.1 | BN8: =BL8*BM8 -> 1.17228 | BO8: =AS8-BN8 -> 4.083452 | BP8: =BO8/AN8 -> 0.19153152
J9: =sum(J4:J7) -> 16000 | N9: =sum(N4:N7) -> 69400 | Q9: =sum(Q4:Q7) -> 9000 | U9: =sum(U4:U7) -> 32450 | AB9: =sum(AB4:AB8) -> 18650 | AI9: =AI8 -> 4619.1
K11: Scenario 1
K12: Product | L12: Plant | M12: Cost | N12: Stock
K13: Inositol | L13: Merywood | M13: =N4 -> 24300 | N13: =J4 -> 5000
K14: Magnesium B6 | L14: Merywood | M14: =N5 -> 24500 | N14: =J5 -> 5000
K15: Probiotic Detox | L15: Merywood | M15: =N6 -> 3100 | N15: =J6 -> 1000
K16: Retinol cream | L16: Merywood | M16: =N7 -> 17500 | N16: =J7 -> 5000
K17: Pet Probiotic | L17: Nutriliq | M17: =AI8 -> 4619.1 | N17: =AE8 -> 890
M18: =sum(M13:M17) -> 74019.1 | N18: =sum(N13:N17) -> 16890
K20: Scenario 2
K21: Product | L21: Plant | M21: Cost | N21: Stock
K22: Inositol | L22: MillMax | M22: =U4 -> 7300 | N22: 2000
K23: Magnesium B6 | L23: MillMax | M23: =U5 -> 9400 | N23: 2000
K24: Probiotic Detox | L24: ERA | M24: =AB6 -> 4070 | N24: =X6 -> 1000
K25: Retinol cream | L25: Merywood | M25: =N7 -> 17500 | N25: =J7 -> 5000
K26: Pet Probiotic | L26: Nutriliq | M26: =AI8 -> 4619.1 | N26: =AE8 -> 890
M27: =sum(M22:M26) -> 42889.1 | N27: =sum(N22:N26) -> 10890 | O27: =Q15
K31: Merywood | L31: Millmax | M31: ERA | N31: Nutriliq | O31: Коммент
I32: Сайт | K32: Merywood | L32: Millmax | M32: https://erascientifico.com | N32: https://nutriliq.eu/en/
I33: Локация | K33: Estonia | L33: Latvia | M33: Latvia | N33: Belgium
I34: Мин партия | K34: 5000 | L34: 1000-3000 | M34: 1000 | N34: 890 | O34: Меривуд готовы сделать вайтлейбл 1000 шт. но их вайтлейбл состав похож на пустышку (например инозитол 25мг в капсуле, против 274 у нас в РФ версии.) Прайват лейбл только от 5000 шт.
I35: НДС | K35: 0.24 | L35: 0.22 | M35: 0.22 | N35: 0.21
I36: условия оплаты | K36: предоплата | L36: предоплата | M36: 60% предоплата | N36: 50% предоплата, далее отсрочка 30д
I37: доставка до Амазон | K37: да | L37: да | M37: да | N37: да
I38: хранение | K38: 2 недели | L38: 2 недели | M38: 2 недели | N38: нет
I39: регистрация этикетки | K39: да | L39: нет | M39: да | N39: да
I40: Эксклюзив на ТМ | K40: нет | L40: Ретинол 6 мес | M40: нет | N40: нет
I41: весь ассортимент | K41: да | L41: нет пребиотика | M41: нет | N41: нет
I42: стоимость MOQ | K42: =M18 -> 74019.1 | L42: =U9 -> 32450 | M42: =AB9 -> 18650 | N42: =AI8 -> 4619.1
I43: наличие сырья | K43: на заказ | L43: на заказ | M43: наличие | N43: на заказ
I44: Комментарии про завод | K44: Регистрируют этикетки под ключ, есть весь ассортимент, кроме собачьего пребиотика | L44: Возможны проблемы с качеством продукции (Информауция от товарки. Делают тесты) | M44: Сырье в наличии, работают быстро, регистрируют этикетки под ключ | N44: Сырье в наличии, работают быстро, регистрируют этикетки под ключ

Sheet Лист3
G12: Sertificates f0r Amazon | H12: yes
G13: Sercificates for EU - all countries or local | H13: EU
G14: Price / LT
G15: Payment rems | H15: 50% 30 days | I15: 30 day
G16: Exclusive
G17: Logistics | H17: pick up - shipping
G18: Packaging - size for sticker | H18: included
G19: Assistance with stickers registration | H19: included
G20: what is the flow to start - tming
G21: what is the production flow - substance on stock?
G24: pre pri podt lacto
G25: 60pc 3 g | H25: 5.19 | I25: 890
H26: 46240
H27: 2 week

Sheet fin mod (копия) Vitalii
B1: Q1 | E1: Q2 | H1: Q3 | K1: Q4
B2: 2026 | C2: 2026 | D2: 2026 | E2: 2026 | F2: 2026 | G2: 2026 | H2: 2026 | I2: 2026 | J2: 2026 | K2: 2026 | L2: 2026 | M2: 2026
B3: jan | C3: feb | D3: mar | E3: apr | F3: may | G3: jun | H3: jul | I3: aug | J3: sep | K3: oct | L3: nov | M3: dec | O3: explanation
A4: Бюджет маркетинг | G4: =G24 -> 5000 | H4: =H24 -> 10000 | I4: =I24 -> 10000 | J4: =J24 -> 10000 | K4: =K24 -> 15000 | L4: =L24 -> 15000 | M4: =M24 -> 15000
A5: Client aqusition
A6: Impressions
A7: CTR
A8: Клики | G8: 20000 | H8: 40000 | I8: 60000 | J8: 60000 | K8: 90000 | L8: 90000 | M8: 90000
A9: CPC
A10: CPA
A12: Конверсия из клика в заказ | F12: 0.02 | G12: 0.02 | H12: 0.02 | I12: 0.02 | J12: 0.02 | K12: 0.02 | L12: 0.02 | M12: 0.02
A13: заказы платные | F13: =F8*F12 -> 0 | G13: =G8*G12 -> 400 | H13: =H8*H12 -> 800 | I13: =I8*I12 -> 1200 | J13: =J8*J12 -> 1200 | K13: =K8*K12 -> 1800 | L13: =L8*L12 -> 1800 | M13: =M8*M12 -> 1800
A14: заказы повторные | G14: =F13*G17 -> 0 | H14: =G13*H17 -> 20 | I14: =H13*I17 -> 40 | J14: =I13*J17 -> 120 | K14: =J13*K17 -> 120 | L14: =K13*L17 -> 180 | M14: =L13*M17 -> 180
A15: итого заказы | F15: =F13+F14 -> 0 | G15: =G13+G14 -> 400 | H15: =H13+H14 -> 820 | I15: =I13+I14 -> 1240 | J15: =J13+J14 -> 1320 | K15: =K13+K14 -> 1920 | L15: =L13+L14 -> 1980 | M15: =M13+M14 -> 1980
A16: Retention
A17: процент повторных заказов | G17: 0.05 | H17: 0.05 | I17: 0.05 | J17: 0.1 | K17: 0.1 | L17: 0.1 | M17: 0.1
A19: средний чек в евро | F19: 25 | G19: 25 | H19: 30 | I19: 30 | J19: 35 | K19: 35 | L19: 40 | M19: 40
A21: выручка в евро | C21: =C15*C19 -> 0 | D21: =D15*D19 -> 0 | E21: =E15*E19 -> 0 | F21: =F19*F15 -> 0 | G21: =G19*G15 -> 10000 | H21: =H19*H15 -> 24600 | I21: =I19*I15 -> 37200 | J21: =J19*J15 -> 46200 | K21: =K19*K15 -> 67200 | L21: =L19*L15 -> 79200 | M21: =M19*M15 -> 79200
A22: Taxes | B22: 0.3 | C22: 0.3 | D22: 0.3 | E22: 0.3 | F22: 0.3 | G22: 0.3 | H22: 0.3 | I22: 0.3 | J22: 0.3 | K22: 0.3 | L22: 0.3 | M22: 0.3
A23: taxes eur | B23: =B21*B22 -> 0 | C23: =C21*C22 -> 0 | D23: =D21*D22 -> 0 | E23: =E21*E22 -> 0 | F23: =F21*F22 -> 0 | G23: =G21*G22 -> 3000 | H23: =H21*H22 -> 7380 | I23: =I21*I22 -> 11160 | ... M23: =M21*M22 -> 23760
A24: расходы на маркетинг | D24: =D4 | F24: 5000 | G24: 5000 | H24: 10000 | I24: 10000 | J24: 10000 | K24: 15000 | L24: 15000 | M24: 15000
A25: Costs
A26: Marketing cost rate
A27: Marketing costs EUR
A28: Costs of payment processing
A29: ФОТ | B29: =payroll!B23 -> 0 | C29: =payroll!C23 -> 0 | D29: =payroll!D23 -> 0 | E29: =payroll!E23 -> 3961.1111 | F29: =payroll!F23 -> 5111.1111 | G29: =payroll!G23 -> 5111.1111 | H29: =payroll!H23 -> 5111.1111 | I29: =payroll!I23 -> 5111.1111 | ... M29: =payroll!M23 -> 5111.1111
A30: Производство продукции | D30: 90000
A31: Регистрационные взносы | D31: 2000 | E31: 2000 | F31: 2000
A32: Консультанты | D32: 1000 | E32: 1000 | F32: 1000
A33: софт, подписки, опер расходы | D33: 1000 | E33: 1000 | F33: 1000 | G33: 500 | H33: 500 | I33: 500 | J33: 500 | K33: 500 | L33: 500 | M33: 500
A34: Logistics
A35: warehouse rent
A36: опер расходы ЮЛ блг | D36: 800 | E36: 800 | F36: 800 | G36: 800 | H36: 800 | I36: 800 | J36: 800 | K36: 800 | L36: 800 | M36: 800
A37: опер расходы ЮЛ гк
A38: Комиссия Амазон | B38: 0.2 | C38: 0.2 | D38: 0.2 | E38: 0.2 | F38: 0.2 | G38: 0.2 | H38: 0.2 | I38: 0.2 | J38: 0.2 | K38: 0.2 | L38: 0.2 | M38: 0.2
A39: Комиссия Амазон евро | B39: =B21*B38 -> 0 | C39: =C21*C38 -> 0 | D39: =D21*D38 -> 0 | E39: =E21*E38 -> 0 | F39: =F21*F38 -> 0 | G39: =G21*G38 -> 2000 | H39: =H21*H38 -> 4920 | I39: =I21*I38 -> 7440 | ... M39: =M21*M38 -> 15840
A40: Итого расходы | B40: =B29+B30+B31+B32+B33+B34+B35+B36+B37+B24+B23 -> 0 | C40: =C29+C30+C31+C32+C33+C34+C35+C36+C37+C24+C23 -> 0 | D40: =D29+D30+D31+D32+D33+D34+D35+D36+D37+D24+D23 -> 94800 | E40: =E29+E30+E31+E32+E33+E34+E35+E36+E37+E24+E23 -> 8761.1111 | F40: =F29+F30+F31+F32+F33+F34+F35+F36+F37+F24+F23 -> 14911.111 | G40: =G29+G30+G31+G32+G33+G34+G35+G36+G37+G24+G23 -> 14411.111 | H40: =H29+H30+H31+H32+H33+H34+H35+H36+H37+H24+H23 -> 23791.111 | I40: =I29+I30+I31+I32+I33+I34+I35+I36+I37+I24+I23 -> 27571.111 | ... M40: =M29+M30+M31+M32+M33+M34+M35+M36+M37+M24+M23 -> 45171.111
A41: CASHFLOW
A42: gross profit | B42: =B21-B40-B39 -> 0 | C42: =C21-C40-C39 -> 0 | D42: =D21-D40-D39 -> -94800 | E42: =E21-E40-E39 -> -8761.1111 | F42: =F21-F40-F39 -> -14911.111 | G42: =G21-G40-G39 -> -6411.1111 | H42: =H21-H40-H39 -> -4111.1111 | I42: =I21-I40-I39 -> 2188.8889 | ... M42: =M21-M40-M39 -> 18188.889
A43: Investments
...

Sheet payroll
B1: Q1 | E1: Q2 | H1: Q3 | K1: Q4
A2: HEADCOUNT | B2: 2026 | C2: 2026 | D2: 2026 | E2: 2026 | F2: 2026 | G2: 2026 | H2: 2026 | I2: 2026 | J2: 2026 | K2: 2026 | L2: 2026 | M2: 2026
B3: jan | C3: feb | D3: mar | E3: apr | F3: may | G3: jun | H3: jul | I3: aug | J3: sep | K3: oct | L3: nov | M3: dec
A4: CDO | D4: 1 | E4: 1 | F4: 1 | G4: 1 | H4: 1 | I4: 1 | J4: 1 | K4: 1 | L4: 1 | M4: 1
A5: Head of project | B5: 1 | C5: 1 | D5: 1 | E5: 1 | F5: 1 | G5: 1 | H5: 1 | I5: 1 | J5: 1 | K5: 1 | L5: 1 | M5: 1
A11: PAYROLL | O11: tax avg
A12: CDO | E12: 199000 | F12: 199000 | G12: 199000 | H12: 199000 | I12: 199000 | J12: 199000 | K12: 199000 | L12: 199000 | M12: 199000 | O12: 0.18
A13: Head of project | E13: 111000 | F13: 111000 | G13: 111000 | H13: 111000 | I13: 111000 | J13: 111000 | K13: 111000 | L13: 111000 | M13: 111000 | O13: 0.15
A14: add | O14: 0.15
O15: 0.15
A17: Client service spec. | F17: 90000 | G17: 90000 | H17: 90000 | I17: 90000 | J17: 90000 | K17: 90000 | L17: 90000 | M17: 90000 | O17: 0.13
A22: Total payroll nett | B22: =sum(B12:B21) -> 0 | C22: =sum(C12:C21) -> 0 | D22: =sum(D12:D21) -> 0 | E22: =sum(E12:E21) -> 310000 | F22: =sum(F12:F21) -> 400000 | G22: =sum(G12:G21) -> 400000 | H22: =sum(H12:H21) -> 400000 | I22: =sum(I12:I21) -> 400000 | ... M22: =sum(M12:M21) -> 400000 | N22: =sum(B22:M22) -> 3510000
A23: Total payroll gorss (RAW) | B23: =(B22*1.15)/90 -> 0 | C23: =(C22*1.15)/90 -> 0 | D23: =(D22*1.15)/90 -> 0 | E23: =(E22*1.15)/90 -> 3961.1111 | F23: =(F22*1.15)/90 -> 5111.1111 | G23: =(G22*1.15)/90 -> 5111.1111 | H23: =(H22*1.15)/90 -> 5111.1111 | I23: =(I22*1.15)/90 -> 5111.1111 | ... M23: =(M22*1.15)/90 -> 5111.1111
